<?xml version="1.0"?>
<robot name="RHexBot" xmlns:xacro="http://ros.org/wiki/xacro">

  <link name="base_link">
        <visual>
            <origin xyz="0 0 0" rpy="0 0 0" />
            <geometry>
                <box size="1 2.5 0.5" />
            </geometry>
            <material name="Cyan">
                <color rgba="0 1.0 1.0 1.0" />
            </material>
        </visual>
        <collision>
            <geometry>
                <box size="1 2.5 0.5" />
            </geometry>
        </collision>
        <inertial>
            <mass value="10"/>
            <inertia ixx="1.0" ixy="0.0" ixz="0.0" iyy="1.0" iyz="0.0" izz="1.0"/>
        </inertial>
    </link>

    <link name="leg_fl">
        <visual>
            <origin xyz="0 0 0" rpy="0 0 0" />
            <geometry>
                <box size="0.25 1 0.25" />
            </geometry>
        </visual>
        <collision>
            <geometry>
                <box size="0.25 1 0.25" />
            </geometry>
        </collision>
        <inertial>
            <mass value="1"/>
            <inertia ixx="1.0" ixy="0.0" ixz="0.0" iyy="1.0" iyz="0.0" izz="1.0"/>
        </inertial>
    </link>

    <link name="leg_fr">
        <visual>
            <origin xyz="0 0 0" rpy="0 0 0" />
            <geometry>
                <box size="0.25 1 0.25" />
            </geometry>
        </visual>
        <collision>
            <geometry>
                <box size="0.25 1 0.25" />
            </geometry>
        </collision>
        <inertial>
            <mass value="1"/>
            <inertia ixx="1.0" ixy="0.0" ixz="0.0" iyy="1.0" iyz="0.0" izz="1.0"/>
        </inertial>
    </link>

    <joint name="body_to_leg_fl" type="continuous">
        <axis rpy="0 0 0" xyz="1 0 0"/>
        <parent link="base_link" />
        <child link="leg_fl" />
        <origin xyz="-0.6125 0 0"/>
    </joint>

    <joint name="body_to_leg_fr" type="continuous">
        <axis rpy="0 0 0" xyz="1 0 0"/>
        <parent link="base_link" />
        <child link="leg_fr" />
        <origin xyz="0.6125 0 0"/>
    </joint>

</robot>